
weight=2
embed_into_distance=2

unacceptable_target_blocks=flowing_water,tfc:fluid/fresh_water,tfc:fluid/salt_water,flowing_lava,lava,Natura:Cloud,red_mushroom_block,brown_mushroom_block,planks,cobblestone,end_stone,obsidian,purpur_block,iron_bars,purpur_slab,purpur_pillar,netherrack,soul_sand,quartz_ore

dimensions=4,12,12
max_leveling=2
leveling_buffer=0
preserve_water=0
preserve_lava=0
preserve_plants=1


rule1=0,100,tfc:gravel/gabbro
rule2=0,100,tfc:fluid/fresh_water,tfc_decoration:cracked_bricks/gabbro,tfc_decoration:mossy_bricks/gabbro,tfc_decoration:cracked_bricks/gabbro,tfc_decoration:mossy_bricks/gabbro,preserveBlock,preserveBlock
rule3=0,100,tfc:fluid/fresh_water,tfc:fluid/fresh_water,tfc:fluid/fresh_water,tfc_decoration:cracked_bricks/gabbro,tfc_decoration:cracked_bricks/gabbro,tfc_decoration:mossy_bricks/gabbro,tfc_decoration:mossy_bricks/gabbro
rule4=0,100,tfc:fluid/fresh_water,tfc:fluid/fresh_water,tfc:fluid/fresh_water,tfc:fluid/fresh_water,tfc:fluid/fresh_water,tfc:fluid/fresh_water,tfc:fluid/fresh_water,tfc:fluid/fresh_water,tfc:fluid/fresh_water,tfc:fluid/fresh_water,tfc:fluid/fresh_water,tfc:fluid/fresh_water,tfc:fluid/fresh_water,tfc:gravel/gabbro,tfc:grass/chert
rule5=0,100,tfc_decoration:cracked_bricks/gabbro,tfc_decoration:mossy_bricks/gabbro
rule6=0,30,tfc:slab/smooth/gabbro-3
rule7=0,30,waterlily
rule8=0,75,tfc_decoration:cracked_bricks/gabbro,tfc_decoration:mossy_bricks/gabbro
rule9=1,50,tfc_decoration:cracked_bricks/gabbro,tfc_decoration:mossy_bricks/gabbro,tfc_decoration:cracked_bricks/gabbro,tfc_decoration:mossy_bricks/gabbro,tfc:fluid/fresh_water


layer
1,1,1,1,1,1,1,1,1,1,1,1
1,1,1,1,1,1,1,1,1,1,1,1
1,1,1,1,1,1,1,1,1,1,1,1
1,1,1,1,1,1,1,1,1,1,1,1
1,1,1,1,1,1,1,1,1,1,1,1
1,1,1,1,1,1,1,1,1,1,1,1
1,1,1,1,1,1,1,1,1,1,1,1
1,1,1,1,1,1,1,1,1,1,1,1
1,1,1,1,1,1,1,1,1,1,1,1
1,1,1,1,1,1,1,1,1,1,1,1
1,1,1,1,1,1,1,1,1,1,1,1
1,1,1,1,1,1,1,1,1,1,1,1
endlayer

layer
2,2,2,2,2,2,2,2,2,2,2,2
2,3,3,3,3,3,3,3,3,3,3,2
2,3,4,4,4,4,4,4,4,4,3,2
2,3,4,4,4,4,4,4,4,4,3,2
2,3,4,4,5,4,4,4,4,4,3,2
2,3,4,4,4,4,4,4,4,4,3,2
2,3,4,4,4,4,4,4,4,4,3,2
2,3,4,4,4,4,4,5,4,4,3,2
2,3,4,4,4,4,4,4,4,4,3,2
2,3,4,4,4,4,4,4,4,4,3,2
2,3,3,3,3,3,3,3,3,3,3,2
2,2,2,2,2,2,2,2,2,2,2,2
endlayer

layer
0,0,0,0,0,0,0,0,0,0,0,0
0,6,6,6,6,6,6,6,6,6,6,0
0,6,7,7,7,7,7,7,7,7,6,0
0,6,7,7,7,7,7,7,7,7,6,0
0,6,7,7,8,7,7,7,7,7,6,0
0,6,7,7,7,7,7,7,7,7,6,0
0,6,7,7,7,7,7,7,7,7,6,0
0,6,7,7,7,7,7,8,7,7,6,0
0,6,7,7,7,7,7,7,7,7,6,0
0,6,7,7,7,7,7,7,7,7,6,0
0,6,6,6,6,6,6,6,6,6,6,0
0,0,0,0,0,0,0,0,0,0,0,0
endlayer

layer
0,0,0,0,0,0,0,0,0,0,0,0
0,0,0,0,0,0,0,0,0,0,0,0
0,0,0,0,0,0,0,0,0,0,0,0
0,0,0,0,0,0,0,0,0,0,0,0
0,0,0,0,9,0,0,0,0,0,0,0
0,0,0,0,0,0,0,0,0,0,0,0
0,0,0,0,0,0,0,0,0,0,0,0
0,0,0,0,0,0,0,9,0,0,0,0
0,0,0,0,0,0,0,0,0,0,0,0
0,0,0,0,0,0,0,0,0,0,0,0
0,0,0,0,0,0,0,0,0,0,0,0
0,0,0,0,0,0,0,0,0,0,0,0
endlayer

